Workbook

Sheet Executive Summary
B2: IMPACTLENS: GTM AND PRICING MODEL
B3: Status: DRAFT for review, 2026-09-30. Pricing is documented; GTM and revenue inputs that the docs lacked are now labelled planning assumptions on 'Planning Inputs' (owner to confirm). Colour key: blue = typed from a source · black = formula · green = linked from another sheet · yellow = key assumption to confirm.
B5: PRODUCT AND CUSTOMER
B6: Item | C6: Summary | F6: Source
B7: Product overview | C7: AI-powered media platform for impact and sustainability organisations. Field photos and video → AI analysis (captions, tags, signals, confidence, SDG mapping) → searchable, org-scoped evidence → before/after comparison, donor-ready reports and campaign copy, with scheduled delivery and public share links. | F7: PRD.md (repo root, outside docs/) §1, §4; IMPACTLENS PRICING MODEL.xlsx › A3
B8: Target customer | C8: NGOs, CSR teams and climate projects holding large volumes of unorganised field media. Users: program managers (org owners) and comms / fundraising staff; donors read shared reports. The tiers target Low / Mid / High 'impact evidence maturity' (proposed criteria on Pricing row 13). | F8: PRD.md (repo root, outside docs/) §1–§2; IMPACTLENS PRICING MODEL.xlsx › row 30
B9: Core value proposition | C9: 'Field evidence → AI insight → donor-ready reports'. Cut report and campaign drafting from hours to minutes, grounded in the org's own assets, with each org's data isolated. | F9: IMPACTLENS PRICING MODEL.xlsx › A3; PRD.md (repo root, outside docs/) §3
B10: GTM strategy | C10: DOCUMENTED: segments, value proposition, product journey, support level per tier, tier fences, a Phase 2 trigger. ASSUMED (Planning Inputs, to confirm): India-first geography, content / referral / connector / share-link channels, self-serve + founder-led motion, funnel rates, CAC ceiling, market size. HYPOTHESIS: position as the report layer for organisations that already have field media; do not lead with 'AI tagging'. | F10: GTM Strategy; ICP & Segmentation
B11: Pricing strategy | C11: Three per-organisation subscription tiers. The annual-billing price is the base; the monthly plan costs annual ÷ (1 − 17%). Tiers are fenced by limits and features (video, semantic search, share links and campaign copy from Pro; scheduled reports from Enterprise). Documented Phase 2 raises prices when SSO, RBAC, audit log, public API and verifier workflow ship. | F11: IMPACTLENS PRICING MODEL.xlsx; Pricing
B13: PRICE POINTS (linked from Pricing)
C14: Starter | D14: Pro | E14: Enterprise | F14: Comment
B15: Price, annual plan (₹ / month) | C15: =Pricing!C15 -> 2999 | D15: =Pricing!D15 -> 7999 | E15: =Pricing!E15 -> 19999 | F15: Documented.
B16: Price, monthly plan (₹ / month) | C16: =Pricing!C17 -> 3613 | D16: =Pricing!D17 -> 9637 | E16: =Pricing!E17 -> 24095 | F16: Calculated: annual ÷ (1 − 17%).
B17: Price, annual plan (USD / month) | C17: =Pricing!C16 -> 31 | D17: =Pricing!D16 -> 83 | E17: =Pricing!E16 -> 208 | F17: Calculated at the workbook's FX rate; indicative.
B18: Phase 2 price, low (₹ / month) | C18: =Pricing!C71 -> 4000 | D18: =Pricing!D71 -> 12000 | E18: =Pricing!E71 -> 29000 | F18: Documented; not in effect.
B19: Phase 2 price, high (₹ / month) | C19: =Pricing!C72 -> 5000 | D19: =Pricing!D72 -> 15000 | E19: =Pricing!E72 -> 39000 | F19: Documented; not in effect.
B20: Gross margin, as modelled | C20: =Pricing!C57 -> 0.85561854 | D20: =Pricing!D57 -> 0.65245656 | E20: =Pricing!E57 -> 0.48747437 | F20: Calculated; cost floor at full allowance use.
B21: Gross margin, published Cloudinary price | C21: =Pricing!C63 -> 0.84227735 | D21: =Pricing!D63 -> 0.62744704 | E21: =Pricing!E63 -> 0.45746521 | F21: Calculated; see contradiction O-01.
B22: Gross margin, all-video upper bound | C22: =Pricing!C66 -> 0.84227735 | D22: =Pricing!D66 -> 0.064876721 | E22: =Pricing!E66 -> -0.66759105 | F22: Calculated stress case; see O-06.
B24: KEY ASSUMPTIONS TO CONFIRM
B25: Cloudinary cost per credit | C25: =Pricing!$C$51 -> 34 | D25: Model uses this; published price implies a higher figure (O-01).
B26: AI cost per vision analysis (₹) | C26: =Pricing!$C$52 -> 0.9 | D26: Unmeasured assumption.
B27: Annual billing discount | C27: =Pricing!$C$7 -> 0.17 | D27: Documented.
B28: USD → INR rate | C28: =Pricing!$C$8 -> 96.07 | D28: Documented, undated.
B29: Organisations for Phase 2 pricing | C29: 50 | D29: Documented trigger (plus API pilot and funder-verification pilots).
B31: KEY METRICS / KPIs
B32: KPI | C32: Target | F32: Source / status
B33: Time to a searchable asset | C33: Under 30 s per image | F33: Documented: PRD.md (repo root, outside docs/) §6
B34: Reports citing ≥ 3 real assets | C34: 100% | F34: Documented: PRD.md (repo root, outside docs/) §6 (not enforced today)
B35: Cross-tenant reads / writes | C35: 0 | F35: Documented: PRD.md (repo root, outside docs/) §6
B36: Paying organisations (Phase 2 trigger) | C36: 50 | F36: Documented: IMPACTLENS PRICING MODEL.xlsx › D72
B37: CAC, conversion, churn, NRR | C37: ="Sign-up → paid "&TEXT('Planning Inputs'!$D$23,"0.0%")&"; CAC ≤ ₹"&TEXT('Revenue Model'!C67,"#,##0")&" / ₹"&TEXT('Revenue Model'!D67,"#,##0")&" / ₹"&TEXT('Revenue Model'!E67,"#,##0")&"; churn ≤ "&TEXT('Revenue Model'!C62,"0.0%")&" / "&TEXT('Revenue Model'!D62,"0.0%")&" / "&TEXT('Revenue Model'!E62,"0.0%")&" a month; NRR "&TEXT('Revenue Model'!C88,"0%") -> Sign-up → paid 10.1%; CAC ≤ ₹30,792 / ₹62,628 / ₹1,75,482; churn ≤ 3.0% / 1.5% / 0.7% a month; NRR 98% | F37: Assumed targets (Planning Inputs; Revenue Model section D).
B39: HOW COMPLETE IS THE EVIDENCE? (counts from 'Assumptions & Sources')
B40: Type | C40: Items
B41: Documented | C41: =COUNTIF('Assumptions & Sources'!$I$6:$I$52,"Documented") -> 27
B42: Calculated | C42: =COUNTIF('Assumptions & Sources'!$I$6:$I$52,"Calculated") -> 8
B43: Assumption | C43: =COUNTIF('Assumptions & Sources'!$I$6:$I$52,"Assumption") -> 8
B44: Hypothesis | C44: =COUNTIF('Assumptions & Sources'!$I$6:$I$52,"Hypothesis") -> 3
B45: Unfilled | C45: =COUNTIF('Assumptions & Sources'!$I$6:$I$52,"TBD") -> 0
B46: Contradicted | C46: =COUNTIF('Assumptions & Sources'!$I$6:$I$52,"Contradicted") -> 1
...

Sheet ICP & Segmentation
B2: ICP & SEGMENTATION
B3: Segments are taken from PRD.md §2 and the problem statement, plus hypotheses from docs/COMPETITIVE-LANDSCAPE.md §3. Buying triggers and decision makers were not in the docs; they are filled as Assumptions (no customer interviews yet). Attractiveness is a weighted score from 'Planning Inputs' section 9. Filter on the Status column.
B5: A · CUSTOMER SEGMENTS
B6: ID | C6: Customer segment | D6: Customer type | E6: Characteristics (documented) | F6: Pain points | G6: Needs / use cases | H6: Buying triggers | I6: Decision makers | J6: Attractiveness | K6: Source | L6: Confidence | M6: Status
B7: S1 | C7: Program teams at NGOs and impact organisations | D7: Buyer and user (persona: 'Program manager', the org owner) | E7: Collects large volumes of photos and video from plantings, installs, cleanups and classrooms. Each org is its own workspace; joining an existing org needs an owner's invite code. | F7: Media sits unorganised. Proving impact to donors means someone manually sorting files, writing captions, finding before/after pairs and drafting reports. The evidence exists, but nobody can search it or cite it. | G7: Upload field media and organise it by project; show progress over time (map, timeline, SDG goals, health score); before/after comparison; keep the org's data isolated. | H7: Donor or grant report deadline; a new funder asking for photo evidence; annual-report season. | I7: Program manager (org owner) chooses; executive director approves spend at Pro and above (assumption). | J7: =TEXT('Planning Inputs'!$H$75,"0.00")&" / 5 (rank "&'Planning Inputs'!$I$75&" of 6)" -> 4.30 / 5 (rank 1 of 6) | K7: PRD.md (repo root, outside docs/) §1, §2, §3 | L7: Documented | M7: Documented
B8: S2 | C8: Comms and fundraising teams | D8: User (persona: 'Comms / fundraising', a member) | E8: Draft donor reports and social campaigns from the org's own assets. | F8: Same as S1; specifically finding the right shot fast and drafting reports and campaigns by hand. | G8: Semantic search over media; impact, summary, campaign and comparison reports (1–4 variants, choice of tone); campaign copy per platform (Instagram, X, LinkedIn, newsletter). | H8: Fundraising campaign or annual report; a social-media push around an event. | I8: Influencer, not a budget holder: head of comms recommends, executive director approves (assumption). | J8: =TEXT('Planning Inputs'!$H$76,"0.00")&" / 5 (rank "&'Planning Inputs'!$I$76&" of 6)" -> 3.75 / 5 (rank 3 of 6) | K8: PRD.md (repo root, outside docs/) §2 | L8: Documented | M8: Documented
B9: S3 | C9: Corporate CSR and sustainability teams | D9: Buyer (named as an intended user of the product) | E9: CSR teams are named in the problem statement. The competitor research found BNZ Impact naming 'Corporates & CSR Teams' as its buyers and selling geo-tagged, verified evidence. | F9: Need evidence that can be verified. ImpactLens today has no GPS, no content hash and a manual 'verified' flag, so it is under-serving this segment (memo §1, §3). | G9: Verifiable evidence packs; funder-facing reporting. | H9: Annual CSR report and board review of Section 135 spend; audits of implementation partners. | I9: CSR head or sustainability lead; procurement signs Enterprise contracts (assumption). | J9: =TEXT('Planning Inputs'!$H$77,"0.00")&" / 5 (rank "&'Planning Inputs'!$I$77&" of 6)" -> 3.55 / 5 (rank 4 of 6) | K9: PRD.md (repo root, outside docs/) §1; docs/COMPETITIVE-LANDSCAPE.md §3 (verified: BNZ Impact page, 2026-09-29) | L9: Medium | M9: Hypothesis
B10: S4 | C10: Governments and sustainability organisations | D10: Named in the hackathon brief | E10: The brief lists 'NGOs, governments, and sustainability organizations' as generators of field media. | F10: As the brief states: manually organising, analysing and verifying media is time-consuming and hard to scale. | G10: Scheme monitoring evidence with data-residency and procurement (tender / GeM) rules (assumption). | H10: Scheme review cycles and audit findings. | I10: Department officer through a tender; long cycle (assumption). | J10: =TEXT('Planning Inputs'!$H$78,"0.00")&" / 5 (rank "&'Planning Inputs'!$I$78&" of 6)" -> 2.35 / 5 (rank 6 of 6) | K10: Hackathon brief (Problem Statement 02; supplied in session, not stored in the repo) | L10: Low | M10: Assumption
B11: S5 | C11: Small and mid NGOs with a photo backlog and no M&E staff | D11: Buyer (proposed gap segment) | E11: Has a library of field photos and video but no monitoring-and-evaluation team. | F11: The priced tools found aim at teams that collect data (capture, forms) or fund programs (M&E suites): no priced plan in the $30–$100 range turns an existing photo library into cited reports. | G11: Turn an existing media library into searchable, cited, donor-ready evidence at low cost. | H11: First institutional grant, or a donor asking for evidence the team cannot find. | I11: Founder or executive director: one decision maker (assumption). | J11: =TEXT('Planning Inputs'!$H$79,"0.00")&" / 5 (rank "&'Planning Inputs'!$I$79&" of 6)" -> 3.85 / 5 (rank 2 of 6) | K11: docs/COMPETITIVE-LANDSCAPE.md §1, §3 (calculated from verified competitor prices) | L11: Low | M11: Hypothesis
B12: S6 | C12: Funder-verification-driven organisations (Phase 2) | D12: Buyer (future) | E12: Multi-funder programs that need verifier sign-off, SSO / RBAC and an audit trail. | F12: Need evidence-grade compliance (per the Phase 2 rationale). | G12: Verification workflow, immutable audit log, public API, multi-funder dashboards, BYOC storage, 99.9% uptime SLA. | H12: Documented trigger for Phase 2 pricing: 50 paying orgs + public API pilot + funder-verification pilots closed. | I12: Funder's M&E lead together with the org's executive director; verifier sign-off (assumption). | J12: =TEXT('Planning Inputs'!$H$80,"0.00")&" / 5 (rank "&'Planning Inputs'!$I$80&" of 6)" -> 3.10 / 5 (rank 5 of 6) | K12: IMPACTLENS PRICING MODEL.xlsx › rows 71–77 | L12: Medium | M12: Documented
B13: S7 | C13: Donors and external stakeholders | D13: Reader, not a buyer | E13: Reads a report through a public read-only link, with no account. | F13: Cannot see the underlying evidence: the share page and its report show text only (memo U8). | G13: Read a report through a public link; ideally see the evidence behind it. | H13: n/a: does not purchase. | I13: n/a | J13: n/a | K13: PRD.md (repo root, outside docs/) §2; docs/COMPETITIVE-LANDSCAPE.md U8 | L13: Medium | M13: Documented
B15: B · TIER FIT (how the documented pricing tiers map to customers)
C16: Tier | D16: Impact-evidence maturity | E16: Price (₹ / month, annual plan) | F16: Segment fit | G16: Status
C17: Starter | D17: =Pricing!C13 -> Low | E17: =Pricing!C15 -> 2999 | F17: Most likely S5 and small S1 teams (inference from 'Low maturity' and the 3-seat, 250-asset limits). | G17: Assumption
C18: Pro | D18: =Pricing!D13 -> Mid | E18: =Pricing!D15 -> 7999 | F18: S1 and S2 teams that need search, campaign copy and share links (inferred from the feature fences). | G18: Assumption
C19: Enterprise | D19: =Pricing!E13 -> High | E19: =Pricing!E15 -> 19999 | F19: S3 and S6 (multi-org, scheduled reports, dedicated support; verification features arrive in Phase 2). | G19: Assumption
B20: Only the maturity label is documented for each tier. The mapping to segments is my inference and is marked Assumption. 'Maturity' has no definition (Open Items O-11).

Sheet GTM Strategy
B2: GTM STRATEGY
B3: Documented rows come from the PRD and the pricing model. Channels, marketing, sales channel, geography, funnel volumes and GTM KPI targets did not exist in the docs; they are now filled from 'Planning Inputs' and marked Assumption. Hypothesis rows come from docs/COMPETITIVE-LANDSCAPE.md.
B5: A · STRATEGY ELEMENTS
B6: Element | C6: Detail | D6: Status | E6: Source | F6: Note
B7: Target segments | C7: Program managers (org owners) and comms/fundraising staff at NGOs, CSR teams and climate projects. Donors read shared reports but do not buy. | D7: Documented | E7: PRD.md (repo root, outside docs/) §2 | F7: See ICP & Segmentation.
B8: Value proposition | C8: 'Field evidence → AI insight → donor-ready reports'. Cut report and campaign drafting from hours to minutes, grounded in the org's own assets, with each org's data strictly isolated. | D8: Documented | E8: IMPACTLENS PRICING MODEL.xlsx › A3; PRD.md (repo root, outside docs/) §3
B9: Positioning | C9: 'The report layer for organisations that already have field photos and video: turn a media library into cited, donor-ready evidence.' Do not position as capture; do not lead with 'AI tagging'. | D9: Hypothesis | E9: docs/COMPETITIVE-LANDSCAPE.md §3 | F9: Needs testing with real buyers. Reason: Cloudinary's Plus plan already lists auto-tagging.
B10: Acquisition channels | C10: 1) Content / SEO: donor-report, CSR-report and before/after templates. 2) Referrals from CSR implementation agencies and NGO capacity-building networks. 3) KoboToolbox / CommCare import connector as a partner listing (memo U12). 4) Public share links and the embeddable report widget as a viral loop (U8). | D10: Assumption | E10: — | F10: Proposed. Volume needed is in the funnel below (row 23). Test the channel mix in the first 90 days.
B11: Marketing approach | C11: Product-led: 14-day free trial plus report templates; one customer case study a month built from consented evidence; webinars with NGO networks ahead of annual-report and CSR-filing season (Apr–Jun, the first quarter of the Indian financial year). | D11: Assumption | E11: —
B12: Sales channel | C12: ='Planning Inputs'!$D$10 -> Self-serve trial and web checkout for Starter and Pro; founder-led sales for Enterprise, CSR and funder buyers. No resellers in year 1. | D12: Assumption | E12: —
B13: Sales motion | C13: Support scales by tier: Email (Starter), Email + Chat (Pro), Dedicated + SLA (Enterprise). Whether Starter/Pro are self-serve and Enterprise is sales-led is an inference, not documented. | D13: Assumption | E13: IMPACTLENS PRICING MODEL.xlsx › D69:H69 | F13: Confirm the motion before building the funnel.
B14: Distribution channel (product) | C14: A web application. Deployment target is undecided: Caddy on a VM, or a Vercel-style host. This affects headers, proxy trust and cron. | D14: Documented | E14: PRD.md (repo root, outside docs/) §7 | F14: Open question in the PRD.
B15: Delivery channels inside the product | C15: Scheduled reports by email, run-summary posts to Slack, public read-only share links, CSV export, print-to-PDF. | D15: Documented | E15: PRD.md (repo root, outside docs/) §4 (F8, F10, F11)
B16: Partner / channel ideas | C16: Embeddable public report widget on partner sites (U8); import connectors from Fulcrum, CommCare and KoboToolbox instead of building capture (U12); WhatsApp delivery of scheduled reports (U13). | D16: Hypothesis | E16: docs/COMPETITIVE-LANDSCAPE.md §5 | F16: Proposed, not decided. Connector APIs and terms not yet checked.
B17: Geographic strategy | C17: ='Planning Inputs'!$D$8 -> India first: INR billing with GST invoices and Razorpay checkout. English-speaking international NGOs billed in USD (indicative prices on Pricing) once a USD checkout exists. | D17: Assumption | E17: IMPACTLENS PRICING MODEL.xlsx › D7; docs/competitors.csv | F17: Resolves Open Items O-04 as a planning assumption; owner to confirm.
B18: Pricing as a GTM lever | C18: Tier fences: video analysis, semantic search, share links and campaign copy start at Pro; scheduled reports start at Enterprise. A 17% discount rewards annual billing. | D18: Documented | E18: IMPACTLENS PRICING MODEL.xlsx › Tier Feature Overview | F18: See Pricing.
B19: Pre-conditions before selling to funder-facing / verification buyers | C19: Provenance hash + GPS (U1), enforced report citations (U2), and enforceable plan limits (U3). | D19: Hypothesis | E19: docs/COMPETITIVE-LANDSCAPE.md §5 (P0) | F19: A recommendation from the audit, not a decision.
B21: B · CUSTOMER JOURNEY AND CONVERSION STAGES (volumes over 12 months, from Planning Inputs section 2)
B22: Stage | C22: What happens (documented product behaviour) | D22: Volume (12 months) | E22: Conversion to next stage | F22: Documented target / source
B23: 1 · Awareness | C23: Content / SEO, partner referrals, connector listing and share links (row 10). | D23: =D24/'Planning Inputs'!$D$16 -> 22772.552 | E23: =IF(AND(ISNUMBER(D23),ISNUMBER(D24),N(D23)>0),D24/D23,"n/a") -> 0.025 | F23: ="Target: "&TEXT(D23,"#,##0")&" site visits in 12 months at "&TEXT('Planning Inputs'!$D$16,"0.0%")&" visit → sign-up." -> Target: 22,773 site visits in 12 months at 2.5% visit → sign-up.
B24: 2 · Sign-up | C24: Email + password sign-up. Creating an org, or joining an existing one with the owner's invite code (F1). | D24: ='Planning Inputs'!$D$14*((1+'Planning Inputs'!$D$15)^12-1)/'Planning Inputs'!$D$15 -> 569.31379 | E24: =IF(AND(ISNUMBER(D24),ISNUMBER(D25),N(D24)>0),D25/D24,"n/a") -> 0.7 | F24: PRD.md (repo root, outside docs/) §4 F1
B25: 3 · First upload | C25: Upload up to 10 MB in the browser, add an external URL, or generate an image with AI (F2). | D25: =D24*'Planning Inputs'!$D$17 -> 398.51966 | E25: =IF(AND(ISNUMBER(D25),ISNUMBER(D26),N(D25)>0),D26/D25,"n/a") -> 0.95 | F25: PRD.md (repo root, outside docs/) §4 F2
B26: 4 · First analysis | C26: AI captions, tags, signals, confidence, SDG mapping; video by frame sampling (F3). | D26: =D25*'Planning Inputs'!$D$18 -> 378.59367 | E26: =IF(AND(ISNUMBER(D26),ISNUMBER(D27),N(D26)>0),D27/D26,"n/a") -> 0.7 | F26: Target: under 30 s from upload to a searchable, tagged image (PRD.md (repo root, outside docs/) §6)
B27: 5 · Value moment | C27: Search, filter, before/after comparison, project map / timeline / health score (F4–F7). | D27: =D26*'Planning Inputs'!$D$19 -> 265.01557 | E27: =IF(AND(ISNUMBER(D27),ISNUMBER(D28),N(D27)>0),D28/D27,"n/a") -> 0.6 | F27: Activated = at least one analysed asset and one generated report (proposed definition; KPI row 49).
B28: 6 · Report or campaign | C28: Generate impact, summary, campaign or comparison reports; campaign copy per platform (F8, F9). | D28: =D27*'Planning Inputs'!$D$20 -> 159.00934 | E28: =IF(AND(ISNUMBER(D28),ISNUMBER(D29),N(D28)>0),D29/D28,"n/a") -> 0.6 | F28: Target: 100% of reports cite at least 3 real org assets (PRD.md (repo root, outside docs/) §6; enforcement is not built, memo U2)
B29: 7 · Share or schedule | C29: Public read-only share link; scheduled email and Slack delivery (F10, F11). | D29: =D28*'Planning Inputs'!$D$21 -> 95.405606 | E29: =IF(AND(ISNUMBER(D29),ISNUMBER(D30),N(D29)>0),D30/D29,"n/a") -> 0.6 | F29: PRD.md (repo root, outside docs/) §4
B30: 8 · Paid conversion / upgrade | C30: Proposed: 14-day opt-in free trial with Pro features (25 analyses, 2 credits), then self-serve checkout for Starter / Pro or a sales call for Enterprise. | D30: =D29*'Planning Inputs'!$D$22 -> 57.243363 | E30: =IF(AND(ISNUMBER(D30),ISNUMBER(D31),N(D30)>0),D31/D30,"n/a") -> 0.90382846 | F30: ="Target: "&TEXT(D30,"0")&" new paying orgs in 12 months = "&TEXT('Planning Inputs'!$D$23,"0.0%")&" of sign-ups (opt-in trial benchmark 8–22%, median 14%)." -> Target: 57 new paying orgs in 12 months = 10.1% of sign-ups (opt-in trial benchmark 8–22%, median 14%).
B31: 9 · Renewal and expansion | C31: Annual plans; Phase 2 repricing when SSO / RBAC / audit log / API ship. | D31: ='Revenue Model'!O48 -> 51.738181 | E31: n/a | F31: Row 31 volume = paying orgs still active at M12 (Revenue Model O48), so E30 is 12-month logo retention.
B32: Volumes are calculated from Planning Inputs section 2; change the sign-up or stage rates there.
B34: C · PHASING
B35: Phase | C35: What it means | D35: Status | E35: Trigger / gate | F35: Source
B36: Phase 1 (now) | C36: Phase 1 subscription prices (Starter / Pro / Enterprise). The PRD lists the product as built and hardening in progress. | D36: Documented | E36: ="In effect from "&TEXT('Planning Inputs'!$D$9,"d mmm yyyy")&" (planning start)." -> In effect from 1 Oct 2026 (planning start). | F36: IMPACTLENS PRICING MODEL.xlsx; PRD.md (repo root, outside docs/) header
B37: Before funder-facing sales | C37: Provenance hash + GPS, enforced citations, enforceable plan limits (P0 in the memo). | D37: Hypothesis | E37: Recommendation; not scheduled. | F37: docs/COMPETITIVE-LANDSCAPE.md §5
B38: Phase 2 | C38: SSO, RBAC, immutable audit log, public API, verifier workflow, BYOC storage, 99.9% uptime SLA; prices rise (see Pricing section 5). | D38: Documented | E38: ="50 paying orgs + public API pilot + funder-verification pilots closed. Modelled 50-org date: "&IF(ISNUMBER('Revenue Model'!C92),TEXT('Revenue Model'!C92,"mmm yyyy"),'Revenue Model'!C92)&"." -> 50 paying orgs + public API pilot + funder-verification pilots closed. Modelled 50-org date: Sep 2027. | F38: IMPACTLENS PRICING MODEL.xlsx › D71:D77
B40: D · KPIs (documented targets first; proposed GTM metrics have NO targets in the docs)
B41: KPI | C41: Definition | D41: Type | E41: Target | F41: Source
B42: Time to a searchable asset | C42: Time from upload to a searchable, tagged asset. | D42: Documented | E42: Under 30 s per image | F42: PRD.md (repo root, outside docs/) §6
B43: Reports citing real assets | C43: Share of generated reports that cite at least 3 real org assets. | D43: Documented | E43: 100% | F43: PRD.md (repo root, outside docs/) §6 (not measured or enforced today)
B44: Cross-tenant reads / writes | C44: Count found by the e2e scoping suite. | D44: Documented | E44: 0 | F44: PRD.md (repo root, outside docs/) §6
B45: Dashboard load | C45: Dashboard interactive time on the seeded database. | D45: Documented | E45: Under 2 s | F45: PRD.md (repo root, outside docs/) §5
...

Sheet Pricing
B2: PRICING
B3: Source of truth: docs/IMPACTLENS PRICING MODEL.xlsx (sheet 'ImpactLens Pricing'). Blue = typed from a document · black = formula · green = linked from another sheet. Section 6 add-ons, overage, discounts and trial are planning assumptions from 'Planning Inputs'. All prices in INR; USD is indicative at the rate below.
B5: 1 · GLOBAL INPUTS
B6: Input | C6: Value | F6: Source / status
B7: Annual billing discount | C7: 0.17 | F7: Documented: IMPACTLENS PRICING MODEL.xlsx › ImpactLens Pricing › D6
B8: USD → INR rate | C8: 96.07 | F8: Documented: IMPACTLENS PRICING MODEL.xlsx › D8 (marked editable). Date and source of the rate are not documented.
B9: Primary currency | C9: INR (₹); USD indicative | F9: Documented: IMPACTLENS PRICING MODEL.xlsx › D7. Target geography is not documented (see Open Items O-04).
B11: 2 · TIERS AND PRICE (per organisation per month; the workbook's COGS block is 'per org / month')
B12: Line | C12: Starter | D12: Pro | E12: Enterprise | F12: Source / note
B13: Impact Evidence Maturity Level | C13: Low | D13: Mid | E13: High | F13: Criteria (proposed, closes Open Items O-11 as an assumption): Low = one programme, media in shared drives, no M&E staff, ≤ 250 assets; Mid = several projects, regular reports to 1–5 funders, up to 5,000 assets; High = multiple programmes or orgs, funder verification or scheduled reporting, an M&E function. Proposed from the tier limits (assumption).
B14: Target customer (as documented) | C14: Low-maturity programs | D14: Mid-maturity programs | E14: High-maturity programs | F14: Only the maturity label is documented; there is no firmographic definition (ICP sheet, section B).
B15: Price: annual plan (₹ / month) | C15: 2999 | D15: 7999 | E15: 19999 | F15: Documented: IMPACTLENS PRICING MODEL.xlsx › D31:F31 (marked star input; 'per-month charges billed annually').
B16: Price: annual plan (USD / month, indicative) | C16: =ROUND(C15/$C$8,0) -> 31 | D16: =ROUND(D15/$C$8,0) -> 83 | E16: =ROUND(E15/$C$8,0) -> 208 | F16: Calculated: ₹ price ÷ USD→INR rate. Mirrors the source workbook's row 32.
B17: Price: monthly plan (₹ / month) | C17: =ROUND(C15/(1-$C$7),0) -> 3613 | D17: =ROUND(D15/(1-$C$7),0) -> 9637 | E17: =ROUND(E15/(1-$C$7),0) -> 24095 | F17: Calculated with the source formula: annual price ÷ (1 − discount). Source: D11 and H34:J34.
B18: Billed per year: annual plan (₹) | C18: =C15*12 -> 35988 | D18: =D15*12 -> 95988 | E18: =E15*12 -> 239988 | F18: Calculated (× 12).
B19: Billed per year: monthly plan (₹) | C19: =C17*12 -> 43356 | D19: =D17*12 -> 115644 | E19: =E17*12 -> 289140 | F19: Calculated (× 12).
B20: Saving from billing annually (₹ / year) | C20: =C19-C18 -> 7368 | D20: =D19-D18 -> 19656 | E20: =E19-E18 -> 49152 | F20: Calculated. Source workbook row 40 (small differences are rounding of the monthly price).
B21: Effective annual discount | C21: =C20/C19 -> 0.16994188 | D21: =D20/D19 -> 0.16996991 | E21: =E20/E19 -> 0.16999377 | F21: Calculated: equals the input discount by construction (it is not independent evidence of price sensitivity).
B22: Billing frequency | C22: Annual (shown per month) or monthly | D22: Annual (shown per month) or monthly | E22: Annual (shown per month) or monthly | F22: Documented: IMPACTLENS PRICING MODEL.xlsx › D9:D10. The monthly plan is priced higher; there is no free tier or trial in the docs.
B23: Support | C23: Email | D23: Email + Chat | E23: Dedicated + SLA | F23: Documented: IMPACTLENS PRICING MODEL.xlsx › D69:H69. The SLA terms are not defined ('99.9% uptime SLA' appears only as a Phase 2 item).
B25: 3 · WHAT EACH TIER INCLUDES (usage limits and features)
B26: Feature / limit | C26: Starter | D26: Pro | E26: Enterprise | F26: Source / note
B27: Organizations (multi-tenant) | C27: 1 | D27: 1 | E27: Unlimited | F27: Documented: IMPACTLENS PRICING MODEL.xlsx › Tier Feature Overview.
B28: Team seats | C28: 3 | D28: 10 | E28: Unlimited | F28: Documented: IMPACTLENS PRICING MODEL.xlsx › Tier Feature Overview.
B29: Media assets in library | C29: 250 | D29: 5,000 | E29: Unlimited | F29: Documented: IMPACTLENS PRICING MODEL.xlsx › Tier Feature Overview. Limits are not enforced in the product today (memo U3).
B30: Video analysis (ffmpeg frame sampling) | C30: — | D30: ✔ | E30: ✔ | F30: Documented: IMPACTLENS PRICING MODEL.xlsx › Tier Feature Overview.
B31: Before/after comparison + impact score | C31: 5 / mo | D31: 100 / mo | E31: Unlimited | F31: Documented: IMPACTLENS PRICING MODEL.xlsx › Tier Feature Overview. Comparison cost is not in COGS (Open Items O-09).
B32: Semantic search (LLM-scored) | C32: — | D32: ✔ | E32: ✔ | F32: Documented: IMPACTLENS PRICING MODEL.xlsx › Tier Feature Overview. Shown as a bare tick, but the COGS line assumes about 300 (Pro) and 1,000 (Enterprise) searches a month: see section 4.
B33: Saved searches | C33: 3 | D33: 50 | E33: Unlimited | F33: Documented: IMPACTLENS PRICING MODEL.xlsx › Tier Feature Overview.
B34: Impact / summary reports (LLM) | C34: 3 / mo | D34: 30 / mo | E34: 150 / mo | F34: Documented: IMPACTLENS PRICING MODEL.xlsx › Tier Feature Overview.
B35: Report variants (4 angles) + clone | C35: — | D35: ✔ | E35: ✔ | F35: Documented: IMPACTLENS PRICING MODEL.xlsx › Tier Feature Overview.
B36: Campaign copy (IG / X / LinkedIn / newsletter) | C36: — | D36: ✔ | E36: ✔ | F36: Documented: IMPACTLENS PRICING MODEL.xlsx › Tier Feature Overview. Cost not in COGS.
B37: Scheduled reports + email delivery (cron) | C37: — | D37: — | E37: ✔ | F37: Documented: IMPACTLENS PRICING MODEL.xlsx › Tier Feature Overview. Cost not in COGS.
... B41: SSO / RBAC / audit log | C41: — | D41: — | E41: Phase 2 | F41: Documented: IMPACTLENS PRICING MODEL.xlsx › Tier Feature Overview. Listed on the Enterprise tier but not built (Open Items O-02).
B42: VLM analysis: images (per month) | C42: =C49 -> 100 | D42: =D49 -> 1000 | E42: =E49 -> 5000 | F42: Documented: IMPACTLENS PRICING MODEL.xlsx › D55:H55. Linked to section 4.
B43: Cloudinary CDN credits included (per month) | C43: =C48 -> 10 | D43: =D48 -> 50 | E43: =E48 -> 150 | F43: Documented: IMPACTLENS PRICING MODEL.xlsx › D66:H66. Linked to section 4.
B44: Add-ons, overage, trial and other discounts are proposed in section 6 (not in the source docs).
B46: 4 · UNIT ECONOMICS (cost floor if the tier's allowances are fully used)
B47: Line | C47: Starter | D47: Pro | E47: Enterprise | F47: Source / note
B48: Cloudinary credits included / mo | C48: 10 | D48: 50 | E48: 150 | F48: Documented: IMPACTLENS PRICING MODEL.xlsx › D18:F18.
...

Sheet Revenue Model
B2: REVENUE MODEL
B3: Sections A and B are exact arithmetic on documented prices. Section C is a 12-month scenario driven entirely by 'Planning Inputs' (labelled assumptions and benchmarks, not documented facts). Sections D and E derive CAC, retention, costs outside COGS and market size from the same inputs.
B5: A · PER-CUSTOMER ECONOMICS (annual-plan price, cost floor at full allowance use)
B6: Per organisation | C6: Starter | D6: Pro | E6: Enterprise
B7: MRR per customer (₹) | C7: =Pricing!C15 -> 2999 | D7: =Pricing!D15 -> 7999 | E7: =Pricing!E15 -> 19999
B8: ARR per customer (₹) | C8: =C7*12 -> 35988 | D8: =D7*12 -> 95988 | E8: =E7*12 -> 239988
B9: COGS per customer (₹ / mo) | C9: =Pricing!C55 -> 433 | D9: =Pricing!D55 -> 2780 | E9: =Pricing!E55 -> 10250
B10: Gross profit per customer (₹ / mo) | C10: =C7-C9 -> 2566 | D10: =D7-D9 -> 5219 | E10: =E7-E9 -> 9749
B11: Gross margin | C11: =C10/C7 -> 0.85561854 | D11: =D10/D7 -> 0.65245656 | E11: =E10/E7 -> 0.48747437
B12: MRR per customer if on the monthly plan (₹) | C12: =Pricing!C17 -> 3613 | D12: =Pricing!D17 -> 9637 | E12: =Pricing!E17 -> 24095
B13: MRR per customer (USD, indicative) | C13: =Pricing!C16 -> 31 | D13: =Pricing!D16 -> 83 | E13: =Pricing!E16 -> 208
B14: COGS assumes every allowance is fully used (a cost floor for a heavy user), so margins here are conservative for light users and ignore hosting, support, payment fees, tax and the uncosted features (Open Items O-09).
B16: B · SCALE ARITHMETIC (N organisations on ONE tier; illustrative multiplication, not a forecast)
B17: N organisations | C17: 1 | D17: 10 | E17: 50 | F17: N = 50 is the documented Phase 2 trigger (IMPACTLENS PRICING MODEL.xlsx › D72). 1 and 10 are scale points, not targets.
B18: MRR (₹) if all N are on… | C18: N = 1 | D18: N = 10 | E18: N = 50
B19: Starter | C19: =C$17*INDEX($C$7:$E$7,1) -> 2999 | D19: =D$17*INDEX($C$7:$E$7,1) -> 29990 | E19: =E$17*INDEX($C$7:$E$7,1) -> 149950
B20: Pro | C20: =C$17*INDEX($C$7:$E$7,2) -> 7999 | D20: =D$17*INDEX($C$7:$E$7,2) -> 79990 | E20: =E$17*INDEX($C$7:$E$7,2) -> 399950
B21: Enterprise | C21: =C$17*INDEX($C$7:$E$7,3) -> 19999 | D21: =D$17*INDEX($C$7:$E$7,3) -> 199990 | E21: =E$17*INDEX($C$7:$E$7,3) -> 999950
B22: ARR (₹) if all N are on… | C22: N = 1 | D22: N = 10 | E22: N = 50
B23: Starter | C23: =C$17*INDEX($C$8:$E$8,1) -> 35988 | D23: =D$17*INDEX($C$8:$E$8,1) -> 359880 | E23: =E$17*INDEX($C$8:$E$8,1) -> 1799400
B24: Pro | C24: =C$17*INDEX($C$8:$E$8,2) -> 95988 | D24: =D$17*INDEX($C$8:$E$8,2) -> 959880 | E24: =E$17*INDEX($C$8:$E$8,2) -> 4799400
B25: Enterprise | C25: =C$17*INDEX($C$8:$E$8,3) -> 239988 | D25: =D$17*INDEX($C$8:$E$8,3) -> 2399880 | E25: =E$17*INDEX($C$8:$E$8,3) -> 11999400
B26: Gross profit / month (₹) if all N are on… | C26: N = 1 | D26: N = 10 | E26: N = 50
B27: Starter | C27: =C$17*INDEX($C$10:$E$10,1) -> 2566 | D27: =D$17*INDEX($C$10:$E$10,1) -> 25660 | E27: =E$17*INDEX($C$10:$E$10,1) -> 128300
B28: Pro | C28: =C$17*INDEX($C$10:$E$10,2) -> 5219 | D28: =D$17*INDEX($C$10:$E$10,2) -> 52190 | E28: =E$17*INDEX($C$10:$E$10,2) -> 260950
B29: Enterprise | C29: =C$17*INDEX($C$10:$E$10,3) -> 9749 | D29: =D$17*INDEX($C$10:$E$10,3) -> 97490 | E29: =E$17*INDEX($C$10:$E$10,3) -> 487450
B31: C · SCENARIO (12 months; annual-plan prices; inputs linked from 'Planning Inputs')
B32: =IF(SUM(D35:O37)+SUM(D38:O39)=0,"NO SCENARIO INPUTS: outputs below show '-'.","Scenario active: driven by Planning Inputs (sign-ups, funnel, mix, churn, upgrades). A planning scenario, not a documented forecast.") -> Scenario active: driven by Planning Inputs (sign-ups, funnel, mix, churn, upgrades). A planning scenario, not a documented forecast.
B33: Line | C33: Monthly churn | D33: M1 | E33: M2 | F33: M3 | G33: M4 | H33: M5 | I33: M6 | J33: M7 | K33: M8 | L33: M9 | M33: M10 | N33: M11 | O33: M12
B34: INPUTS
B35: New customers: Starter | D35: ='Planning Inputs'!$D$14*(1+'Planning Inputs'!$D$15)^0*'Planning Inputs'!$D$23*'Planning Inputs'!$D$34 -> 1.809864 | E35: ='Planning Inputs'!$D$14*(1+'Planning Inputs'!$D$15)^1*'Planning Inputs'!$D$23*'Planning Inputs'!$D$34 -> 1.9546531 | F35: ='Planning Inputs'!$D$14*(1+'Planning Inputs'!$D$15)^2*'Planning Inputs'!$D$23*'Planning Inputs'!$D$34 -> 2.1110254 | G35: ='Planning Inputs'!$D$14*(1+'Planning Inputs'!$D$15)^3*'Planning Inputs'!$D$23*'Planning Inputs'!$D$34 -> 2.2799074 | H35: ='Planning Inputs'!$D$14*(1+'Planning Inputs'!$D$15)^4*'Planning Inputs'!$D$23*'Planning Inputs'!$D$34 -> 2.4623 | I35: ='Planning Inputs'!$D$14*(1+'Planning Inputs'!$D$15)^5*'Planning Inputs'!$D$23*'Planning Inputs'!$D$34 -> 2.659284 | J35: ='Planning Inputs'!$D$14*(1+'Planning Inputs'!$D$15)^6*'Planning Inputs'!$D$23*'Planning Inputs'!$D$34 -> 2.8720267 | K35: ='Planning Inputs'!$D$14*(1+'Planning Inputs'!$D$15)^7*'Planning Inputs'!$D$23*'Planning Inputs'!$D$34 -> 3.1017888 | L35: ='Planning Inputs'!$D$14*(1+'Planning Inputs'!$D$15)^8*'Planning Inputs'!$D$23*'Planning Inputs'!$D$34 -> 3.349932 | M35: ='Planning Inputs'!$D$14*(1+'Planning Inputs'!$D$15)^9*'Planning Inputs'!$D$23*'Planning Inputs'!$D$34 -> 3.6179265 | N35: ='Planning Inputs'!$D$14*(1+'Planning Inputs'!$D$15)^10*'Planning Inputs'!$D$23*'Planning Inputs'!$D$34 -> 3.9073606 | O35: ='Planning Inputs'!$D$14*(1+'Planning Inputs'!$D$15)^11*'Planning Inputs'!$D$23*'Planning Inputs'!$D$34 -> 4.2199495
B36: New customers: Pro | D36: ='Planning Inputs'!$D$14*(1+'Planning Inputs'!$D$15)^0*'Planning Inputs'!$D$23*'Planning Inputs'!$D$35 -> 0.904932 | E36: ='Planning Inputs'!$D$14*(1+'Planning Inputs'!$D$15)^1*'Planning Inputs'!$D$23*'Planning Inputs'!$D$35 -> 0.97732656 | F36: ='Planning Inputs'!$D$14*(1+'Planning Inputs'!$D$15)^2*'Planning Inputs'!$D$23*'Planning Inputs'!$D$35 -> 1.0555127 | G36: ='Planning Inputs'!$D$14*(1+'Planning Inputs'!$D$15)^3*'Planning Inputs'!$D$23*'Planning Inputs'!$D$35 -> 1.1399537 | H36: ='Planning Inputs'!$D$14*(1+'Planning Inputs'!$D$15)^4*'Planning Inputs'!$D$23*'Planning Inputs'!$D$35 -> 1.23115 | I36: ='Planning Inputs'!$D$14*(1+'Planning Inputs'!$D$15)^5*'Planning Inputs'!$D$23*'Planning Inputs'!$D$35 -> 1.329642 | J36: ='Planning Inputs'!$D$14*(1+'Planning Inputs'!$D$15)^6*'Planning Inputs'!$D$23*'Planning Inputs'!$D$35 -> 1.4360134 | K36: ='Planning Inputs'!$D$14*(1+'Planning Inputs'!$D$15)^7*'Planning Inputs'!$D$23*'Planning Inputs'!$D$35 -> 1.5508944 | L36: ='Planning Inputs'!$D$14*(1+'Planning Inputs'!$D$15)^8*'Planning Inputs'!$D$23*'Planning Inputs'!$D$35 -> 1.674966 | M36: ='Planning Inputs'!$D$14*(1+'Planning Inputs'!$D$15)^9*'Planning Inputs'!$D$23*'Planning Inputs'!$D$35 -> 1.8089633 | N36: ='Planning Inputs'!$D$14*(1+'Planning Inputs'!$D$15)^10*'Planning Inputs'!$D$23*'Planning Inputs'!$D$35 -> 1.9536803 | O36: ='Planning Inputs'!$D$14*(1+'Planning Inputs'!$D$15)^11*'Planning Inputs'!$D$23*'Planning Inputs'!$D$35 -> 2.1099747
B37: New customers: Enterprise | D37: ='Planning Inputs'!$D$14*(1+'Planning Inputs'!$D$15)^0*'Planning Inputs'!$D$23*'Planning Inputs'!$D$36 -> 0.301644 | E37: ='Planning Inputs'!$D$14*(1+'Planning Inputs'!$D$15)^1*'Planning Inputs'!$D$23*'Planning Inputs'!$D$36 -> 0.32577552 | F37: ='Planning Inputs'!$D$14*(1+'Planning Inputs'!$D$15)^2*'Planning Inputs'!$D$23*'Planning Inputs'!$D$36 -> 0.35183756 | G37: ='Planning Inputs'!$D$14*(1+'Planning Inputs'!$D$15)^3*'Planning Inputs'!$D$23*'Planning Inputs'!$D$36 -> 0.37998457 | H37: ='Planning Inputs'!$D$14*(1+'Planning Inputs'!$D$15)^4*'Planning Inputs'!$D$23*'Planning Inputs'!$D$36 -> 0.41038333 | I37: ='Planning Inputs'!$D$14*(1+'Planning Inputs'!$D$15)^5*'Planning Inputs'!$D$23*'Planning Inputs'!$D$36 -> 0.443214 | J37: ='Planning Inputs'!$D$14*(1+'Planning Inputs'!$D$15)^6*'Planning Inputs'!$D$23*'Planning Inputs'!$D$36 -> 0.47867112 | K37: ='Planning Inputs'!$D$14*(1+'Planning Inputs'!$D$15)^7*'Planning Inputs'!$D$23*'Planning Inputs'!$D$36 -> 0.51696481 | L37: ='Planning Inputs'!$D$14*(1+'Planning Inputs'!$D$15)^8*'Planning Inputs'!$D$23*'Planning Inputs'!$D$36 -> 0.55832199 | M37: ='Planning Inputs'!$D$14*(1+'Planning Inputs'!$D$15)^9*'Planning Inputs'!$D$23*'Planning Inputs'!$D$36 -> 0.60298775 | N37: ='Planning Inputs'!$D$14*(1+'Planning Inputs'!$D$15)^10*'Planning Inputs'!$D$23*'Planning Inputs'!$D$36 -> 0.65122677 | O37: ='Planning Inputs'!$D$14*(1+'Planning Inputs'!$D$15)^11*'Planning Inputs'!$D$23*'Planning Inputs'!$D$36 -> 0.70332491
B38: Upgrades: Starter → Pro (customers) | D38: 0 | E38: =D45*'Planning Inputs'!$D$40 -> 0.03619728 | F38: =E45*'Planning Inputs'!$D$40 -> 0.073480478 | G38: =F45*'Planning Inputs'!$D$40 -> 0.11202696 | H38: =G45*'Planning Inputs'!$D$40 -> 0.15202376 | I38: =H45*'Planning Inputs'!$D$40 -> 0.19366857 | J38: =I45*'Planning Inputs'!$D$40 -> 0.23717082 | K38: =J45*'Planning Inputs'!$D$40 -> 0.28275282 | L38: =K45*'Planning Inputs'!$D$40 -> 0.33065095 | ... O38: =N45*'Planning Inputs'!$D$40 -> 0.49084595
B39: Upgrades: Pro → Enterprise (customers) | D39: 0 | E39: =D46*'Planning Inputs'!$D$41 -> 0.00904932 | F39: =E46*'Planning Inputs'!$D$41 -> 0.018958325 | G39: =F46*'Planning Inputs'!$D$41 -> 0.029774299 | H39: =G46*'Planning Inputs'!$D$41 -> 0.041549748 | I39: =H46*'Planning Inputs'!$D$41 -> 0.054342742 | J39: =I46*'Planning Inputs'!$D$41 -> 0.068217279 | K39: =J46*'Planning Inputs'!$D$41 -> 0.083243689 | L39: =K46*'Planning Inputs'!$D$41 -> 0.099499069 | ... O39: =N46*'Planning Inputs'!$D$41 -> 0.15652182
B40: Monthly churn by tier | D40: Linked from Planning Inputs section 4 (benchmark ranges in the note).
B41: Monthly churn: Starter | C41: ='Planning Inputs'!$D$37 -> 0.03 | D41: Planning Inputs: SMB SaaS benchmark 3–7% a month.
B42: Monthly churn: Pro | C42: ='Planning Inputs'!$D$38 -> 0.015 | D42: Planning Inputs: Mid-market benchmark 0.5–1.5% a month.
B43: Monthly churn: Enterprise | C43: ='Planning Inputs'!$D$39 -> 0.007 | D43: Planning Inputs: Enterprise benchmark < 0.5–0.7% a month.
B44: OUTPUTS
...

Sheet Competitive Positioning
B2: COMPETITIVE POSITIONING
B3: Source: docs/competitors.csv and docs/COMPETITIVE-LANDSCAPE.md (verified 2026-09-29); the seven rows previously unverified were re-researched on 2026-09-30 through a search tool (Medium confidence unless the pricing page itself was read). 'Not stated on the page read' is NOT evidence of absence. Quote-only prices are shown in text, not in the USD column.
B5: ImpactLens reference (linked from Pricing) | E5: Pro tier price (USD / month) | F5: =Pricing!D16 -> 83
B7: Competitor | C7: Role | D7: Target customer | E7: Pricing (public, as documented) | F7: USD / mo (lowest paid, monthly equiv.) | G7: × ImpactLens Pro price | H7: Product positioning | I7: Key strengths (stated on source) | J7: Relevant gaps (evidence-limited) | K7: Our differentiation | L7: Confidence | M7: Last verified | N7: Source URL
B8: Fulcrum | C8: capture-verify | D8: Field teams (segments not stated on pricing page) | E8: Professional $43/user/mo; Elite $55/user/mo; Enterprise custom; min 5 users | F8: 215 | G8: =F8/$F$5 -> 2.5903614 | H8: Mobile field data capture with photos, video, audio, GPS | I8: capture with geotag / timestamp; offline capture | J8: Not stated on the page read: photo/video AI (not proof of absence). | K8: ImpactLens does not capture media; it analyses and reports on it. This competitor is stronger on proof of capture. Possible import partner (hypothesis, memo U12). | L8: High | M8: 2026-09-29 | N8: https://www.fulcrumapp.com/pricing
B9: CommCare (Dimagi) | C9: capture-verify | D9: NGOs, governments, social enterprises, donors and foundations, researchers | E9: Standard $100/mo; Pro $500/mo; Advanced $1,000/mo; Enterprise $4,000+/mo | F9: 100 | G9: =F9/$F$5 -> 1.2048193 | H9: Mobile data collection and case management | I9: None stated on the page read | J9: Not stated on the page read: photo/video AI (not proof of absence). | K9: ImpactLens does not capture media; it analyses and reports on it. This competitor is stronger on proof of capture. Possible import partner (hypothesis, memo U12). | L9: High | M9: 2026-09-29 | N9: https://commcare.dimagi.com/pricing/
B10: Sealr (UNDP Digital X) | C10: capture-verify | D10: UN and government agencies in humanitarian response; field staff, partners, affected communities | E10: not stated | H10: Timestamped, geolocated, AI-verified and blockchain-secured photo/video capture on a map dashboard | I10: capture with geotag / timestamp | J10: Page (© 2022) does not explain what the 'AI-verified' step does; product status unknown. | K10: ImpactLens does not capture media; it analyses and reports on it. This competitor is stronger on proof of capture. Possible import partner (hypothesis, memo U12). | L10: Medium | M10: 2026-09-29 | N10: https://digitalx.undp.org/catalogs/sealr.html
B11: Tella | C11: capture-verify | D11: Activists, journalists, human-rights defenders | E11: Free forever (vendor statement) | F11: Free | H11: Encrypted offline-first photo/video/audio capture | I11: offline capture | J11: Not stated on the page read: photo/video AI (not proof of absence). | K11: ImpactLens does not capture media; it analyses and reports on it. This competitor is stronger on proof of capture. Possible import partner (hypothesis, memo U12). | L11: High | M11: 2026-09-29 | N11: https://tella.app
B12: BNZ Impact | C12: capture-verify | D12: Corporates and CSR teams, NGOs, foundations, restoration developers, sustainability teams | E12: No pricing on page | H12: Baseline capture, geo-tagged photos, satellite verification, exportable evidence packs | I12: capture with geotag / timestamp | J12: Not stated on the page read: photo/video AI (not proof of absence). | K12: ImpactLens does not capture media; it analyses and reports on it. This competitor is stronger on proof of capture. Possible import partner (hypothesis, memo U12). | L12: High | M12: 2026-09-29 | N12: https://bnzgreen.io/impact
B13: KoboToolbox | C13: capture-verify | D13: Humanitarian and development field data collection | E13: Community free (5,000 submissions / mo); Professional $159/mo ($129 billed annually); Teams $289/mo ($249 annually) | F13: 129 | G13: =F13/$F$5 -> 1.5542169 | H13: Survey/form data collection | I13: Offline form capture with GPS, photo, audio and video questions; free Community plan | J13: Media is stored as form attachments; no photo / video AI or report drafting stated (not proof of absence). | K13: Import partner, not a rival: ImpactLens analyses the photos Kobo collects (memo U12). Chauka already imports from Kobo, which shows the connector pattern works. | L13: Medium | M13: 2026-09-30 | N13: https://www.kobotoolbox.org/pricing/
B14: Sopact | C14: report-ai | D14: Nonprofits, foundations, social enterprises, mission-driven organisations | E14: Power $299/mo (2 users, 500 AI analyses/yr, 1,500 responses); Growth $799/mo (3 users, 2,000 analyses/yr); Enterprise custom; setup from $200/hr, 10-hour minimum | F14: 299 | G14: =F14/$F$5 -> 3.6024096 | H14: AI analysis of forms, files and feedback into funder-aligned reports | I14: reports / evidence packs | J14: Not stated on the page read: photo/video AI (not proof of absence). Home page describes forms, files and feedback; no photo analysis stated. | K14: ImpactLens grounds reports in analysed media evidence and lists the source assets; this competitor's evidence base is text or forms, as stated on its page. Hypothesis: buyers will pay more for media-grounded evidence. | L14: High | M14: 2026-09-29 | N14: https://sopact.com
B15: ReportsAI | C15: report-ai | D15: Grassroots NGOs to multinational enterprises | E15: No pricing on home page; /pricing returned 404 | H15: AI reporting against SDGs, IRIS+, GRI, ESG with offline multilingual data capture | I15: SDG / IRIS+ / GRI alignment; offline capture | J15: Not stated on the page read: photo/video AI (not proof of absence). | K15: ImpactLens grounds reports in analysed media evidence and lists the source assets; this competitor's evidence base is text or forms, as stated on its page. Hypothesis: buyers will pay more for media-grounded evidence. | L15: High | M15: 2026-09-29 | N15: https://reports-ai.app
B16: ImpactDraft | C16: report-ai | D16: Small local NGOs to international organisations | E16: Free demo (3 reports); Basic $9/mo (30 reports); Pro $19/mo (100 reports); Enterprise $49/mo (unlimited) | F16: 9 | G16: =F16/$F$5 -> 0.10843373 | H16: Donor report generator (7 report types, 5 languages) | I16: reports / evidence packs | J16: Not stated on the page read: photo/video AI (not proof of absence). Text only; no media evidence stated. | K16: ImpactLens grounds reports in analysed media evidence and lists the source assets; this competitor's evidence base is text or forms, as stated on its page. Hypothesis: buyers will pay more for media-grounded evidence. | L16: High | M16: 2026-09-29 | N16: https://impactdraft.org
B17: engage by Kindsight | C17: report-ai | D17: Nonprofits: education, healthcare, arts, community foundations, faith-based | E17: No pricing on page | H17: AI donor communications and grant-proposal drafting | I17: AI donor copy | J17: Not stated on the page read: photo/video AI (not proof of absence). | K17: ImpactLens grounds reports in analysed media evidence and lists the source assets; this competitor's evidence base is text or forms, as stated on its page. Hypothesis: buyers will pay more for media-grounded evidence. | L17: High | M17: 2026-09-29 | N17: https://kindsight.io/engage
B18: DevResults | C18: me-suite | D18: Global development organisations managing funded programs | E18: Setup $33,800 (<=$5M program) to $103,400 (<=$100M); annual $28,000 (<=$5M), $49,000 (<=$25M), $70,000 (<=$50M); training $5,000-$15,000; unlimited users and storage | F18: 2333 | G18: =F18/$F$5 -> 28.108434 | H18: Monitoring and evaluation software | I18: None stated on the page read | J18: Not stated on the page read: photo/video AI (not proof of absence). | K18: Different job (program-level M&E) and a different budget. Far cheaper than ImpactLens Enterprise (see ratio) but ImpactLens offers no indicator / logframe management. Hypothesis: competes for the same reporting budget. | L18: High | M18: 2026-09-29 | N18: https://www.devresults.com/pricing
B19: Chauka | C19: me-suite | D19: Development organisations that plan with logical frameworks | E19: Open source; no public price found | H19: Open-source M&E / logframe (prior doc) | I19: Logframe design, indicator targets and actuals, budget lines, KoboToolbox and Google Sheets import, quarterly donor reports | J19: No photo / video evidence handling stated (not proof of absence). | K19: Different job (programme-level M&E / logframes) and a different budget; ImpactLens offers no indicator management. Complementary: its analysed media could feed their indicators. | L19: Medium | M19: 2026-09-30 | N19: https://chauka.org
B20: MONIC | C20: me-suite | D20: Researchers, nonprofits, government agencies | E20: Open source (AGPL-3.0); no public price | H20: Open-source M&E (prior doc) | I20: KPI tracking, theory-of-change builder, logframes, surveys with optional ChatGPT analysis, document repository | J20: No photo / video AI stated (not proof of absence). | K20: Different job (programme-level M&E / logframes) and a different budget; ImpactLens offers no indicator management. Complementary: its analysed media could feed their indicators. | L20: Medium | M20: 2026-09-30 | N20: https://www.monic.tech/
B21: MEInsight | C21: me-suite | D21: unknown | E21: Not public | H21: Open-source M&E / logframe | I21: None stated on the page read | J21: Last commit 2023-11-08: dormant. | K21: Different job (program-level M&E) and a different budget. Far cheaper than ImpactLens Enterprise (see ratio) but ImpactLens offers no indicator / logframe management. Hypothesis: competes for the same reporting budget. | L21: Medium | M21: 2026-09-29 | N21: https://github.com/edc-it/MEInsight
B22: Uwazi (HURIDOCS) | C22: me-suite | D22: Human-rights documentation | E22: Not public | H22: Evidence document collections with search | I22: None stated on the page read | J22: — | K22: Different job (program-level M&E) and a different budget. Far cheaper than ImpactLens Enterprise (see ratio) but ImpactLens offers no indicator / logframe management. Hypothesis: competes for the same reporting budget. | L22: Medium | M22: 2026-09-29 | N22: https://github.com/HURIDOCS/uwazi
B23: Amp Impact (Vera Solutions) | C23: me-suite | D23: Salesforce-based nonprofits (prior doc) | E23: From $7,000 / year; nonprofit discounts; custom quotes (Capterra listing) | F23: 583 | G23: =F23/$F$5 -> 7.0240964 | H23: Salesforce-packaged impact measurement (prior doc) | I23: Native Salesforce app: grant and portfolio management, indicator tracking, work planning; 17,000+ users in 150+ countries | J23: Requires Salesforce; no media AI stated (not proof of absence). | K23: Different job and budget (Salesforce M&E, ≈ 7× ImpactLens Pro). ImpactLens is lighter and media-first; no CRM needed. | L23: Medium | M23: 2026-09-30 | N23: https://www.verasolutions.org/ampimpact/
B24: Watershed | C24: esg-suite | D24: Enterprise ESG and carbon disclosure | E24: Custom quote only; third-party estimates $50k–$250k+ / year, median ≈ $70k (Vendr) | H24: Carbon/ESG reporting (prior doc) | I24: Enterprise carbon accounting (Scope 1–3) and disclosure reporting | J24: Carbon and financial data, not field media. | K24: Different buyer and job (corporate carbon disclosure). Overlaps only with S3 CSR teams' reporting budget; candidate to drop from the landscape. | L24: Medium | M24: 2026-09-30 | N24: https://watershed.com
B25: Persefoni | C25: esg-suite | D25: Enterprise ESG and carbon disclosure | E25: Pro: free (single user); Advanced: custom quote | F25: Free | H25: Carbon/ESG reporting (prior doc) | I25: Scope 1–3 (all 15 categories), report builder for CSRD / ISSB / CDP, AI copilot; SSO and SOC 2 on Advanced | J25: Carbon data, not field media. | K25: Different buyer and job (corporate carbon disclosure). Overlaps only with S3 CSR teams' reporting budget; candidate to drop from the landscape. | L25: High | M25: 2026-09-30 | N25: https://www.persefoni.com/pricing
B26: Sweep | C26: esg-suite | D26: Enterprise ESG and carbon disclosure | E26: No public price; Starter and Pro tiers by quote (third-party listing) | H26: Carbon/ESG reporting (prior doc) | I26: Carbon management, supplier data collection, CSRD reporting | J26: Carbon data, not field media. | K26: Different buyer and job (corporate carbon disclosure). Overlaps only with S3 CSR teams' reporting budget; candidate to drop from the landscape. | L26: Medium | M26: 2026-09-30 | N26: https://www.sweep.net
B27: Ecodrive ImpactIQ | C27: marketplace | D27: Nonprofits selling verified impact to corporate partners; corporate buyers | E27: Projects from $0.45 per unit; Enterprise from a $50k annual impact commitment | H27: Donor portals and dashboards showing timestamps, geo-coordinates and photos of each partner's contribution | I27: capture with geotag / timestamp; SDG / IRIS+ / GRI alignment | J27: Not stated on the page read: photo/video AI, baseline / before-after (not proof of absence). Page describes a corporate-donation marketplace, not a media library. | K27: Different model: sells verified impact units to corporate buyers. Not comparable on price. | L27: High | M27: 2026-09-29 | N27: https://www.ecodrive.community/impactiq
B28: Cloudinary | C28: platform-vendor | D28: Developers and brands managing image/video | E28: Free 25 credits; Plus $99/mo ($89/mo annual) 225 credits incl. auto-tagging; Advanced $249/mo ($224 annual) 600 credits; Enterprise custom; 1 credit = 1,000 transformations or 1 GB storage or 1 GB image bandwidth (2 GB video) | F28: 89 | G28: =F28/$F$5 -> 1.0722892 | H28: Media storage, transformation, CDN, DAM, AI auto-tagging | I28: photo/video AI | J28: — | K28: Cloudinary is ImpactLens's storage and CDN supplier and also offers its own auto-tagging. ImpactLens differentiates on workflow (evidence chain → cited report → schedule), not on tagging. | L28: High | M28: 2026-09-29 | N28: https://cloudinary.com/documentation/cloudinary_ai_content_analysis_addon
B29: TextIt / RapidPro | C29: channel | D29: Organisations messaging contacts by SMS and WhatsApp | E29: $25/mo for the first 1,000 messaged contacts, then $0.01 per additional contact; special pricing for registered non-profits | F29: 25 | G29: =F29/$F$5 -> 0.30120482 | H29: Messaging flows and campaigns | I29: None stated on the page read | J29: — | K29: A possible delivery channel (SMS / WhatsApp), not a rival. | L29: High | M29: 2026-09-29 | N29: https://textit.com/pricing
B30: MIRL Aftermath | C30: reference-oss | D30: Heritage professionals, conservators, human-rights researchers | E30: Free | F30: Free | H30: Before/after photo condition dossiers for courts and UNESCO submissions | I30: baseline / before-after; reports / evidence packs | J30: — | K30: Design reference; not sold to buyers. | L30: High | M30: 2026-09-29 | N30: https://github.com/mirl-ucsb/mirl-aftermath
B31: impact-vision | C31: reference-oss | D31: VC and impact investment funds | E31: Free | F31: Free | H31: AI agent mapping reported impact to IRIS+, SDGs and 20+ ESG frameworks | I31: SDG / IRIS+ / GRI alignment | J31: — | K31: Design reference; not sold to buyers. | L31: High | M31: 2026-09-29 | N31: https://github.com/joejoe168168/impact-vision
B32: impact-reporter-ai | C32: reference-oss | D32: n/a (repository removed) | E32: n/a | H32: n/a: repository returns HTTP 404 | I32: n/a | J32: Repository returns HTTP 404. | K32: None needed: dead link. Remove from the landscape. | L32: Dead | M32: 2026-09-29 | N32: https://github.com/maree217/impact-reporter-ai
B34: PRICE SUMMARY (calculated from the rows above)
B35: Competitors with a numeric price | E35: =COUNT(F8:F32) -> 9
B36: Lowest (USD / month) | E36: =MIN(F8:F32) -> 9
B37: Median (USD / month) | E37: =MEDIAN(F8:F32) -> 129
B38: Highest (USD / month) | E38: =MAX(F8:F32) -> 2333
B39: Priced below ImpactLens Starter | E39: =COUNTIF(F8:F32,"<"&Pricing!C16) -> 2
B40: Priced above ImpactLens Enterprise | E40: =COUNTIF(F8:F32,">"&Pricing!E16) -> 4
B41: Prices are each vendor's lowest paid public plan, converted to a monthly equivalent; they cover different products (text report writers, form-based M&E, field capture, M&E suites), so this is context, not a like-for-like comparison. Detail: docs/IMPACTLENS PRICING MODEL.xlsx › 'Price Benchmark'.

Sheet Planning Inputs
B2: PLANNING INPUTS
B3: Every number the source documents did not give lives here. Blue = typed assumption or public figure · black = formula · yellow = key assumption the owner should confirm. Change a blue cell and every sheet updates. Prepared 2026-09-30. Benchmarks are third-party figures read through a search tool: re-read before external use.
B6: 1 · GEOGRAPHY, DATES AND SALES MOTION
B7: ID | C7: Input | D7: Value | E7: Unit | F7: Basis / source | G7: Type
B8: P01 | C8: Launch geography and billing currency | D8: India first: INR billing with GST invoices and Razorpay checkout. English-speaking international NGOs billed in USD (indicative prices on Pricing) once a USD checkout exists. | E8: text | F8: Prices are INR-primary (IMPACTLENS PRICING MODEL.xlsx › D7). India holds the reachable, reporting-obliged base counted in section 6. Resolves Open Items O-04 as a planning assumption. | G8: Assumption
B9: P02 | C9: Planning start (month M1) | D9: 46296 | E9: date | F9: First month after this workbook was prepared (2026-09-30). | G9: Assumption
B10: P03 | C10: Sales motion | D10: Self-serve trial and web checkout for Starter and Pro; founder-led sales for Enterprise, CSR and funder buyers. No resellers in year 1. | E10: text | F10: Follows the support model (Email / Email + Chat / Dedicated + SLA; IMPACTLENS PRICING MODEL.xlsx › row 69). | G10: Assumption
B12: 2 · FUNNEL (organisations; each rate is conversion from the previous stage)
B13: ID | C13: Input | D13: Value | E13: Unit | F13: Basis / source | G13: Type
B14: P04 | C14: New sign-ups in M1 | D14: 30 | E14: orgs / month | F14: Sized so the documented Phase 2 trigger (50 paying orgs) is reached inside 12 months at the rates below. | G14: Assumption
B15: P05 | C15: Sign-up growth | D15: 0.08 | E15: per month | F15: Early-stage content + referral growth; no measured traffic exists yet. | G15: Assumption
B16: P06 | C16: Site visit → sign-up | D16: 0.025 | E16: rate | F16: B2B SaaS visit-to-sign-up typically 1–3% (saashero.net, orbix.studio 2026 conversion benchmarks). | G16: Benchmark
B17: P07 | C17: Sign-up → first upload | D17: 0.7 | E17: rate | F17: Upload is the first action after creating an org (PRD F1–F2). | G17: Assumption
B18: P08 | C18: First upload → first analysis | D18: 0.95 | E18: rate | F18: Analysis runs automatically on upload (PRD F3); the loss is failed or unsupported files. | G18: Assumption
B19: P09 | C19: First analysis → value moment | D19: 0.7 | E19: rate | F19: Value moment = search, filter, compare or project view used (PRD F4–F7). | G19: Assumption
B20: P10 | C20: Value moment → first report / campaign | D20: 0.6 | E20: rate | F20: Activation = ≥ 1 analysed asset and ≥ 1 generated report (proposed definition). | G20: Assumption
B21: P11 | C21: Report → share or schedule | D21: 0.6 | E21: rate | F21: Share link or scheduled delivery (PRD F10–F11). | G21: Assumption
B22: P12 | C22: Share → paid | D22: 0.6 | E22: rate | F22: End of the free trial below. | G22: Assumption
